Workbook
Name temp: '[1]univ apc spend 2012-13'!#REF!

Sheet Cleaned
A1: PMID | B1: PMCID | C1: ID type | D1: Publisher | E1: Journal title | F1: Code | G1: Article title | H1: COST | I1: Links | J1: Gender | K1: County | L1: % Int | M1: % Ext | N1: Replies | O1: Check
B2: PMC3378987 | C2: PMC | D2: Elsevier | E2: Academy of Nutrition and Dietetics | F2: AND | G2: Parent support and parent mediated behaviours are associated with children's sugary beverage consumption | H2: 2379.54 | I2: 934 | J2: 0 | K2: 41 | L2: 0.94164318 | M2: 0.058356816 | N2: 0
B3: PMC3780468 | C3: PMC | D3: American Chemical Society | E3: ACS Chemical Biology | F3: CB | G3: A Novel Allosteric Inhibitor of the Uridine Diphosphate N-Acetylglucosamine Pyrophosphorylase from Trypanosoma brucei. | H3: 1294.59 | I3: 823 | J3: 0 | K3: 45 | L3: 0.67563786 | M3: 0.32436214 | N3: 0
B4: PMC3621575 | C4: PMC | D4: American Chemical Society | E4: ACS Chemical Biology | F4: CB | G4: Chemical proteomic analysis reveals the drugability of the kinome of Trypanosoma brucei. | H4: 1294.78 | I4: 866 | K4: 48 | L4: 0.98747019 | M4: 0.012529811 | N4: 0
C5: Blank | D5: American Chemical Society | E5: ACS Chemical Biology | F5: CB | G5: Discovery of β2 Adrenergic Receptor Ligands Using Biosensor Fragment Screening of Tagged Wild-Type Receptor | H5: 947.07 | I5: 76 | J5: 1 | K5: 11 | L5: 0.0036687967 | M5: 0.9963312 | N5: 0
A6: 24015914 | B6: PMC3833349 | C6: PMID + PMC | D6: American Chemical Society | E6: ACS Chemical Biology | F6: CB | G6: Discovery of an allosteric inhibitor binding site in 3-oxo-acyl-ACP reductase from Pseudomonas aeruginosa | H6: 1267.76 | J6: 1 | K6: 21 | L6: 0.08205373 | M6: 0.91794627 | N6: 0
B7: PMC3805332 | C7: PMC | D7: American Chemical Society | E7: ACS Chemical Biology | F7: CB | G7: Synthesis of alpha-glucan in mycobacteria involves a hetero-octameric complex of trehalose synthase TreS and maltokinase Pep2 | H7: 2286.73 | I7: 179 | J7: 0 | K7: 9 | L7: 0.64735029 | M7: 0.35264971 | N7: 0
B8: PMC3656742 | C8: PMC | D8: American Chemical Society | E8: ACS Chemical Neuroscience | F8: CN | G8: Continuous online microdialysis using microfluidic sensors: dynamic neuro-metabolic changes during spreading depolarisation | H8: 1186.8 | I8: 45 | J8: 1 | K8: 18 | L8: 0.42829475 | M8: 0.57170525 | N8: 0
B9: PMC3584654 | C9: PMC | D9: American Chemical Society | E9: ACS Nano | F9: NANO | G9: Hydroxy-terminated conjugated polymer nanoparticles have near-unity bright fraction | H9: 642.89 | I9: 60 | J9: 0 | K9: 17 | L9: 0.27927524 | M9: 0.72072476 | N9: 0
A10: 23373658 | C10: PMID | D10: American Chemical Society | E10: ACS Nano | F10: NANO | G10: Skin dendritic cell targeting via microneedle arrays laden with antigen-encapsulated poly-D,L-lactide-co-glycolide nanoparticles induces efficient antitumor and antiviral immune responses. | H10: 693.39 | I10: 606 | J10: 0 | L10: 0.84485895 | M10: 0.15514105 | N10: 0
B11: PMC3727331 | C11: PMC | D11: International Union of Crystallography | E11: Acta Crystallographica Section D: Biological Crystallography | F11: BIOC | G11: Clustering procedures for the optimal selection of data sets from multiple crystals in macromolecular crystallography | H11: 771.42 | I11: 480 | J11: 1 | K11: 22 | L11: 0.90950792 | M11: 0.090492082 | N11: 0
B12: PMC3565438 | C12: PMC | D12: International Union of Crystallography | E12: Acta Crystallographica Section D: Biological Crystallography | F12: BIOC | G12: Intensity statistics in the presence of translational non-crystallographic symmetry | H12: 773.74 | I12: 690 | J12: 1 | K12: 3 | L12: 0.65722673 | M12: 0.34277327 | N12: 0
B13: PMC3668577 | C13: PMC | D13: International Union of Crystallography | E13: Acta Crystallographica Section F: Structural Biology and Crystallization Communications | F13: STRUC | G13: Structure of diaminohydroxyphosphoribosylaminopyrimidine deaminase/5-amino-6-(5-phosphoribosylamino)uracil reductase from Acinetobacter baumannii. | H13: 785.6 | I13: 603 | K13: 32 | L13: 0.54983986 | M13: 0.45016014 | N13: 0
B14: PMC3606566 | C14: PMC | D14: International Union of Crystallography | E14: Acta Crystallographica Section F: Structural Biology and Crystallization Communications | F14: STRUC | G14: Structure of Pseudomonas aeruginosa inosine 5'-monophosphate dehydrogenase | H14: 807.67 | I14: 485 | J14: 0 | K14: 40 | L14: 0.5395541 | M14: 0.4604459 | N14: 0
B15: PMC3498934 | C15: PMC | D15: International Union of Crystallography | E15: Acta Crystallographica Section D: Biological Crystallography | F15: BIOC | G15: Nearest-cell: a fast and easy tool for locating crystal matches in the PDB. | H15: 757.18 | I15: 15 | J15: 0 | K15: 49 | L15: 0.9176209 | M15: 0.082379105 | N15: 0
A16: 22993091 | B16: PMC3447403 | C16: PMID + PMC | D16: International Union of Crystallography | E16: Acta Crystallographica Section D: Biological Crystallography | F16: BIOC | G16: Crystallization, dehydration and experimental phasing of WbdD, a bifunctional kinase and methyltransferase from Escherichia coli O9a | H16: 774.19 | I16: 376 | J16: 1 | K16: 15 | L16: 0.54700917 | M16: 0.45299083 | N16: 0
B17: PMC3087623 | C17: PMC | D17: International Union of Crystallography | E17: Acta Crystallographica Section D: Biological Crystallography | F17: ACTD | G17: Structure of HLA-A*0301 in complex with a peptide of proteolipid protein: insights into the role of HLA-A alleles in susceptibility to multiple sclerosis. | H17: 750.16 | I17: 904 | J17: 1 | K17: 19 | L17: 0.10131625 | M17: 0.89868375 | N17: 0
B18: PMC3808818 | C18: PMC | D18: Society for Publication of Acta Dermato-Venereologica | E18: Acta Dermato-Venereologica | F18: ACTV | G18: The Importance of a Full Clinical Examination: Assessment of Index Lesions Referred to a Skin Cancer Clinic Without a Total Body Skin Examination Would Miss One in Three Melanomas | H18: 653.96 | I18: 322 | J18: 1 | K18: 25 | L18: 0.18407886 | M18: 0.81592114 | N18: 0
A19: 23828613 | C19: PMID | D19: Springer | E19: Acta Diabetologica | F19: ACTD | G19: A rare SNP in pre-miR-34a is associated with increased levels of miR-34a in pancreatic beta cells | H19: 2336.28 | I19: 544 | J19: 0 | L19: 0.21081329 | M19: 0.78918671 | N19: 0
B20: PMC3374517 | C20: PMC | D20: International Union of Crystallography | E20: Acta Crystallographica Section F: Structural Biology and Crystallization Communications | F20: ACTF | G20: Crystallization and preliminary crystallographic analysis of the major capsid proteins VP16 and VP17 of bacteriophage P23-77 | H20: 754.9 | I20: 476 | J20: 1 | K20: 19 | L20: 0.29987596 | M20: 0.70012404 | N20: 0
B21: PMC3549237 | C21: PMC | D21: Springer | E21: Acta Neuropathologica | F21: ACTN | G21: Overexpression of human wild-type FUS causes progressive motor neuron degeneration in an age- and dose-dependent fashion | H21: 1901.04 | I21: 666 | J21: 0 | L21: 0.29481324 | M21: 0.70518676 | N21: 0
C22: Blank | D22: Springer | E22: Acta Neuropathologica | F22: ACTN | G22: α-Synucleinopathy associated with G51D SNCA mutation: A link between Parkinson's disease and multiple system atrophy? | H22: 1884.01 | I22: 94 | J22: 1 | K22: 10 | L22: 0.38723498 | M22: 0.61276502 | N22: 0
B23: PMC3661931 | C23: PMC | D23: Springer | E23: Acta Neuropathologica | F23: ACTN | G23: Insufficient OPC migration into demyelinated lesions is a cause of poor remyelination in MS and mouse models | H23: 2250.97 | I23: 62 | J23: 1 | K23: 26 | L23: 0.32758913 | M23: 0.67241087 | N23: 0
B24: PMC3535376 | C24: PMC | D24: Springer | E24: Acta Neuropathologica | F24: ACTN | G24: Unravelling the enigma o selective vulnerability in neurodegeneration: motor neurons resistant to degeneration in ALS show distinct gene expression characteristics and decreased susceptibility to excitotoxicity | I24: 188 | J24: 1 | K24: 34 | L24: 0.0191216 | M24: 0.9808784 | N24: 0
B25: PMC3798121 | C25: PMC | D25: Wiley | E25: Acta Ophthalmologica | F25: ACTO | G25: Visual and psychological morbidity among patients with autosomal dominant optic atrophy | H25: 2270.16 | I25: 764 | J25: 0 | K25: 15 | L25: 0.8045102 | M25: 0.1954898 | N25: 0
A26: 21624095 | B26: PMC3734623 | C26: PMID + PMC | D26: Wiley | E26: Acta Physiol | F26: ACTP | G26: Integration of transient receptor potential canonical channels with lipids | H26: 1991.5 | I26: 513 | J26: 0 | K26: 8 | L26: 0.34607205 | M26: 0.65392795 | N26: 0
C27: Blank | D27: Wiley | E27: Addiction | F27: ADCT | G27: Acute alcohol-related dysfunction as a predictor of employment status in a longitudinal study of working age men in Izhevsk, Russia. | H27: 1919.51 | I27: 180 | J27: 0 | K27: 43 | L27: 0.96653617 | M27: 0.033463833 | N27: 0
A28: 23734913 | C28: PMID | D28: Wiley | E28: Addiction | F28: ADCT | G28: Childhood conduct disorder trajectories, prior risk factors and cannabis use at age 16: birth cohort study | H28: 2352.94 | I28: 520 | J28: 0 | K28: 31 | L28: 0.086637113 | M28: 0.91336289 | N28: 0
C29: Blank | D29: Springer | E29: Advances in Experimental Medicine and Biology | F29: AEMB | G29: Wavelet cross-correlation to investigate regional variations in cerebral oxygenation in infants supported on extracorporeal membrane oxygenation | H29: 1928.45 | I29: 818 | J29: 0 | K29: 15 | L29: 0.78811469 | M29: 0.21188531 | N29: 0
C30: Blank | D30: Springer | E30: Advances in Experimental Medicine and Biology | F30: AEMB | G30: Modelling Cerebrovascular Reactivity: A Novel Near-Infrared Biomarker of Cerebral Autoregulation? | H30: 1928.46 | I30: 153 | J30: 1 | K30: 1 | L30: 0.46789626 | M30: 0.53210374 | N30: 0
C31: Blank | D31: Springer | E31: Advances in Experimental Medicine and Biology | F31: AEMB | G31: Normobaric hyperoxia does not change optical scattering or pathlength but does increase oxidised cytochrome C oxidase concentration in patients with brain injury | H31: 1928.46 | I31: 606 | J31: 0 | K31: 20 | L31: 0.32231037 | M31: 0.67768963 | N31: 0
C32: Blank | D32: Springer | E32: Advances in Experimental Medicine and Biology | F32: AEMB | G32: Oscillations in cerebral haemodynamics in patients with falciparum malaria | H32: 1928.46 | I32: 288 | J32: 1 | K32: 2 | L32: 0.45128438 | M32: 0.54871562 | N32: 0
A33: 21948184 | B33: PMC3528370 | C33: PMID + PMC | D33: Springer | E33: Age | F33: AGEA | G33: The dominant human conjunctival epithelial CD8αβ+ T cell population is maintained with age but the number of CD4+ T cells increases. | H33: 2338.28 | I33: 528 | J33: 1 | K33: 9 | L33: 0.26363814 | M33: 0.73636186 | N33: 0
A34: 23340916 | C34: PMID | D34: Springer | E34: Age | F34: AGEA | G34: Voluntary exercise can strengthen the circadian system in aged mice | H34: 2002 | I34: 420 | J34: 1 | K34: 45 | L34: 0.10124067 | M34: 0.89875933 | N34: 0
A35: 23672932 | B35: PMC3684112 | C35: PMID + PMC | D35: Oxford University Press | E35: Age and Ageing | F35: AGEA | G35: Early diagnosis and treatment of HIV infection: magnitude of benefit is greatest in older adults | H35: 2040 | I35: 371 | J35: 1 | K35: 25 | L35: 0.99817275 | M35: 0.0018272506 | N35: 0
C36: Blank | D36: Cambridge University Press | E36: Ageing and Society | F36: AGES | G36: Who cares? Implications of care-giving and -receiving by HIV-infected or -affected older | H36: 1695 | I36: 363 | J36: 0 | K36: 2 | L36: 0.88108645 | M36: 0.11891355 | N36: 0
C37: Blank | D37: Wiley | E37: Aging Cell | F37: AGIC | G37: TORC1 signaling inhibition by rapamycin and caffeine affect lifespan, global gene expression and cell proliferation of fission yeast | H37: 1970.57 | I37: 288 | K37: 41 | L37: 0.51888946 | M37: 0.48111054 | N37: 0
B38: PMC3713766 | C38: PMC | D38: Wolters Kluwer | E38: AIDS | F38: AIDAIDS | G38: HIV infected adolescents in Southern Africa can achieve good treatment outcomes: Results from a large retrospective cohort study. | H38: 1968.63 | I38: 372 | J38: 0 | K38: 27 | L38: 0.72814813 | M38: 0.27185187 | N38: 0
B39: PMC3748854 | C39: PMC | D39: Wolters Kluwer | E39: AIDS | F39: AIDAIDS | G39: Evaluation of an empiric risk screening score to identify acute and early HIV-1 infection among MSM in Coastal Kenya. | H39: 1834.77 | I39: 968 | J39: 0 | L39: 0.55407174 | M39: 0.44592826 | N39: 1582
B40: PMC3647051 | C40: PMC | D40: Wolters Kluwer | E40: AIDS | F40: AIDAIDS | G40: Grassroots Community Organisations' Contribution to the Scale-Up of HIV Testing and Counselling Services in Zimbabwe | H40: 2374.52 | I40: 202 | J40: 1 | K40: 20 | L40: 0.43837387 | M40: 0.56162613 | N40: 0
...

Sheet Summary
A1: Data2Clean - cleaning summary
A3: Identifier type (PMC / PMID / both / blank)
A4: ID type | B4: Rows | C4: Share
A5: PMC | B5: =COUNTIF(Cleaned!$C$2:$C$2128,A5) -> 1391 | C5: =B5/B$9 -> 0.65397273
A6: PMID | B6: =COUNTIF(Cleaned!$C$2:$C$2128,A6) -> 197 | C6: =B6/B$9 -> 0.092618712
A7: PMID + PMC | B7: =COUNTIF(Cleaned!$C$2:$C$2128,A7) -> 257 | C7: =B7/B$9 -> 0.12082746
A8: Blank | B8: =COUNTIF(Cleaned!$C$2:$C$2128,A8) -> 282 | C8: =B8/B$9 -> 0.1325811
A9: Total | B9: =SUM(B5:B8) -> 2127
A10: PMC present in total (PMC + both) | B10: =B5+B7 -> 1648
A11: PMID present in total (PMID + both) | B11: =B6+B7 -> 454
A13: Missing values: before vs after
A14: Column (original) | B14: Truly blank before | C14: 'na' text before | D14: Other placeholder text before | E14: Blank after | F14: 'na' text after
A15: PMID/PMCID | B15: 199 | C15: 0 | D15: 83 | E15: =COUNTBLANK(Cleaned!C2:C2128)*0+COUNTIF(Cleaned!C$2:C$2128,"Blank") -> 282 | F15: 0
A16: Publisher | B16: 0 | C16: 0 | D16: 0 | E16: =COUNTBLANK(Cleaned!D2:D2128) -> 0 | F16: =COUNTIF(Cleaned!D2:D2128,"na") -> 0
A17: Journal title | B17: 0 | C17: 1 | D17: 0 | E17: =COUNTBLANK(Cleaned!E2:E2128) -> 1 | F17: =COUNTIF(Cleaned!E2:E2128,"na") -> 0
A18: Code | B18: 67 | C18: 0 | D18: 0 | E18: =COUNTBLANK(Cleaned!F2:F2128) -> 67 | F18: =COUNTIF(Cleaned!F2:F2128,"na") -> 0
A19: Article title | B19: 0 | C19: 0 | D19: 0 | E19: =COUNTBLANK(Cleaned!G2:G2128) -> 0 | F19: =COUNTIF(Cleaned!G2:G2128,"na") -> 0
A20: COST | B20: 0 | C20: 0 | D20: 0 | E20: =COUNTBLANK(Cleaned!H2:H2128) -> 1 | F20: =COUNTIF(Cleaned!H2:H2128,"na") -> 0
A21: Links | B21: 206 | C21: 0 | D21: 0 | E21: =COUNTBLANK(Cleaned!I2:I2128) -> 206 | F21: =COUNTIF(Cleaned!I2:I2128,"na") -> 0
A22: Gender | B22: 66 | C22: 0 | D22: 0 | E22: =COUNTBLANK(Cleaned!J2:J2128) -> 66 | F22: =COUNTIF(Cleaned!J2:J2128,"na") -> 0
A23: County | B23: 0 | C23: 227 | D23: 0 | E23: =COUNTBLANK(Cleaned!K2:K2128) -> 227 | F23: =COUNTIF(Cleaned!K2:K2128,"na") -> 0
A24: % Int | B24: 0 | C24: 0 | D24: 0 | E24: =COUNTBLANK(Cleaned!L2:L2128) -> 0 | F24: =COUNTIF(Cleaned!L2:L2128,"na") -> 0
A25: % Ext | B25: 0 | C25: 0 | D25: 0 | E25: =COUNTBLANK(Cleaned!M2:M2128) -> 0 | F25: =COUNTIF(Cleaned!M2:M2128,"na") -> 0
A26: Replies | B26: 0 | C26: 0 | D26: 0 | E26: =COUNTBLANK(Cleaned!N2:N2128) -> 0 | F26: =COUNTIF(Cleaned!N2:N2128,"na") -> 0
A28: Rule applied: every missing value is an empty cell. 'na', '-', 'In Process', 'Pending', 'Epub ahead of print...' and similar placeholders were blanked.
A29: Price outlier fence (3 x IQR): above 5422. Row 24 (7,299,879.12) was removed as an obvious error; see Review.

Sheet Review
A1: Excel row | B1: Column | C1: Value | D1: Why it needs a human look
A2: 24 | B2: COST | C2: 7299879.12 | D2: ERROR: implausible cost removed (original 7,299,879.12)
A3: 86 | B3: COST | C3: 45.94 | D3: Review: very low cost (below 100)
A4: 1343 | B4: COST | C4: 13200 | D4: Review: very high cost (above 5422)
A5: 1931 | B5: COST | C5: 6000 | D5: Review: very high cost (above 5422)
A6: 2064 | B6: COST | C6: 5760 | D6: Review: very high cost (above 5422)
A7: 476 | B7: Publisher | C7: PubMed | D7: Not a recognisable publisher name (or unverified) - kept as is
A8: 587 | B8: Publisher | C8: Pion | D8: Not a recognisable publisher name (or unverified) - kept as is
A9: 882 | B9: Publisher | C9: Research Media Ltd | D9: Not a recognisable publisher name (or unverified) - kept as is
A10: 1189 | B10: Publisher | C10: Coaction | D10: Not a recognisable publisher name (or unverified) - kept as is
A11: 1192 | B11: Publisher | C11: Open Access Reg Ltd | D11: Not a recognisable publisher name (or unverified) - kept as is
A12: 1248 | B12: Publisher | C12: PubMed Central | D12: Not a recognisable publisher name (or unverified) - kept as is
A13: 1931 | B13: Publisher | C13: Public.service.co.uk | D13: Not a recognisable publisher name (or unverified) - kept as is
... A48: 1151 | B48: Article title | C48: Mast Cell subsets & their functional modulation by the Acanthocheilonema vitae product, ES... | D48: Citation text appended to the title - not removed

Sheet Publisher changes
A1: Original | B1: Cleaned | C1: Rows
A2: ACS | B2: American Chemical Society | C2: 7
A3: ACS (Amercian Chemical Society) Publications | B3: American Chemical Society | C3: 5
A4: ACS Publications | B4: American Chemical Society | C4: 2
A5: AMERICAN CHEMICAL SOCIETY | B5: American Chemical Society | C5: 1
A6: American Chemical Society Publications | B6: American Chemical Society | C6: 1
A7: The American Physiological Society | B7: American Physiological Society | C7: 1
A8: AMBSB | B8: American Society for Biochemistry and Molecular Biology | C8: 1
A9: American Soc for Biochemistry and Molecular Biology | B9: American Society for Biochemistry and Molecular Biology | C9: 1
A10: American Society for Biochemistry and Molecular Biolgy | B10: American Society for Biochemistry and Molecular Biology | C10: 1
A11: ASBMB | B11: American Society for Biochemistry and Molecular Biology | C11: 46
A12: ASBMB Cadmus | B12: American Society for Biochemistry and Molecular Biology | C12: 1
A13: ASBMB/Cadmus | B13: American Society for Biochemistry and Molecular Biology | C13: 1
... A194: Wolters Kluwers | B194: Wolters Kluwer | C194: 1

Sheet Journal changes
A1: Original | B1: Cleaned | C1: Rows
A2: ACS NANO | B2: ACS Nano | C2: 1
A3: Acta Crystallographica Section D, Biological Crystallography | B3: Acta Crystallographica Section D: Biological Crystallography | C3: 1
A4: Acta Crystallographica, Section D | B4: Acta Crystallographica Section D: Biological Crystallography | C4: 1
A5: Acta Crystallography D | B5: Acta Crystallographica Section D: Biological Crystallography | C5: 1
A6: Acta D | B6: Acta Crystallographica Section D: Biological Crystallography | C6: 1
A7: ACTA F | B7: Acta Crystallographica Section F: Structural Biology and Crystallization Communications | C7: 1
A8: Acta Dermato Venereologica | B8: Acta Dermato-Venereologica | C8: 1
A9: Acta Neuropathol | B9: Acta Neuropathologica | C9: 1
A10: Acta Opthalmologica | B10: Acta Ophthalmologica | C10: 1
A11: AGE | B11: Age | C11: 1
A12: Ageing & Society | B12: Ageing and Society | C12: 1
A13: AIDS Behav | B13: AIDS and Behavior | C13: 1
... A308: The Vet. Journal | B308: Veterinary Journal | C308: 1

Sheet ID changes
A1: Excel row | B1: Original PMID/PMCID | C1: PMID | D1: PMCID | E1: What was done
A2: 10 | B2: 23373658 | C2: 23373658 | E2: bare 8-digit number read as PMID
A3: 24 | B3: 3535376 | D3: PMC3535376 | E3: bare 7-digit number read as PMCID
A4: 26 | B4: 21624095 PMCID: PMC3734623 | C4: 21624095 | D4: PMC3734623 | E4: bare 8-digit number read as PMID
A5: 27 | B5: In Process | E5: not an ID, blanked: In Process
A6: 28 | B6: 23734913 | C6: 23734913 | E6: bare 8-digit number read as PMID
A7: 33 | B7: 21948184 PMC3528370 | C7: 21948184 | D7: PMC3528370 | E7: bare 8-digit number read as PMID
A8: 34 | B8: 23340916 | C8: 23340916 | E8: bare 8-digit number read as PMID
A9: 37 | B9: print published August 2013 | E9: not an ID, blanked: print published August 2013
A10: 39 | B10: 3748854 | D10: PMC3748854 | E10: bare 7-digit number read as PMCID
A11: 41 | B11: 3633780 | D11: PMC3633780 | E11: bare 7-digit number read as PMCID
A12: 42 | B12: In Process | E12: not an ID, blanked: In Process
A13: 53 | B13: 23514390 | C13: 23514390 | E13: bare 8-digit number read as PMID
A14: 54 | B14: 3516067 | D14: PMC3516067 | E14: bare 7-digit number read as PMCID
A15: 55 | B15: 23599091 | C15: 23599091 | E15: bare 8-digit number read as PMID
A16: 56 | B16: 22971149 PMC3466778 | C16: 22971149 | D16: PMC3466778 | E16: bare 8-digit number read as PMID
A17: 63 | B17: 3813311 | D17: PMC3813311 | E17: bare 7-digit number read as PMCID
A18: 71 | B18: 3567269 | D18: PMC3567269 | E18: bare 7-digit number read as PMCID
A19: 73 | B19: published Sept 2013 | E19: not an ID, blanked: published Sept 2013
A20: 74 | B20: 3947303 | D20: PMC3947303 | E20: bare 7-digit number read as PMCID
A21: 77 | B21: 3708126 | D21: PMC3708126 | E21: bare 7-digit number read as PMCID
A22: 79 | B22: PMID: 23409903 23409903 | C22: 23409903 | E22: bare 8-digit number read as PMID
A23: 90 | B23: 23072351 | C23: 23072351 | E23: bare 8-digit number read as PMID
A24: 92 | B24: 23670821 PMC3738939 | C24: 23670821 | D24: PMC3738939 | E24: bare 8-digit number read as PMID
A25: 114 | B25: 23877697 | C25: 23877697 | E25: bare 8-digit number read as PMID
A26: 117 | B26: 23758132 | C26: 23758132 | E26: bare 8-digit number read as PMID
A27: 118 | B27: Not yet available | E27: not an ID, blanked: Not yet available
A28: 119 | B28: 21903599 | C28: 21903599 | E28: bare 8-digit number read as PMID
A29: 120 | B29: 24061777 | C29: 24061777 | E29: bare 8-digit number read as PMID
A30: 125 | B30: 23740368 PMC3840700 | C30: 23740368 | D30: PMC3840700 | E30: bare 8-digit number read as PMID
A31: 126 | B31: 23460124 PMC3715109 | C31: 23460124 | D31: PMC3715109 | E31: bare 8-digit number read as PMID
A32: 129 | B32: In Process | E32: not an ID, blanked: In Process
A33: 134 | B33: 22302008 PMC3405838 | C33: 22302008 | D33: PMC3405838 | E33: bare 8-digit number read as PMID
A34: 139 | B34: 23025831 PMC3462035 | C34: 23025831 | D34: PMC3462035 | E34: bare 8-digit number read as PMID
A35: 140 | B35: 23731076 PMC3670620 | C35: 23731076 | D35: PMC3670620 | E35: bare 8-digit number read as PMID
A36: 141 | B36: 23244291 PMC3569044 | C36: 23244291 | D36: PMC3569044 | E36: bare 8-digit number read as PMID
A37: 145 | B37: 23162054 | C37: 23162054 | E37: bare 8-digit number read as PMID
A38: 146 | B38: 23713614 | C38: 23713614 | E38: bare 8-digit number read as PMID
A39: 150 | B39: 3685266 | D39: PMC3685266 | E39: bare 7-digit number read as PMCID
A40: 173 | B40: 23458425 PMC3630740 | C40: 23458425 | D40: PMC3630740 | E40: bare 8-digit number read as PMID
...

Sheet Original
A1: PMID/PMCID | B1: Publisher | C1: Journal title | D1: Code | E1: Article title | F1: COST | G1: Links | H1: Gender | I1: County | J1: % Int | K1: % Ext | L1: Replies
A2: PMC3378987 | B2: Elsevier | C2: Academy of Nutrition and Dietetics | D2: AND | E2: Parent support and parent mediated behaviours are associated with children's sugary beverage consumption | F2: 2379.54 | G2: 934 | H2: 0 | I2: 41 | J2: 0.94164318 | K2: 0.058356816 | L2: 0
A3: PMCID: PMC3780468 | B3: ACS (Amercian Chemical Society) Publications | C3: ACS Chemical Biology | D3: CB | E3: A Novel Allosteric Inhibitor of the Uridine Diphosphate N-Acetylglucosamine Pyrophosphorylase from Trypanosoma brucei. | F3: 1294.59 | G3: 823 | H3: 0 | I3: 45 | J3: 0.67563786 | K3: 0.32436214 | L3: 0
A4: PMCID: PMC3621575 | B4: ACS (Amercian Chemical Society) Publications | C4: ACS Chemical Biology | D4: CB | E4: Chemical proteomic analysis reveals the drugability of the kinome of Trypanosoma brucei. | F4: 1294.78 | G4: 866 | I4: 48 | J4: 0.98747019 | K4: 0.012529811 | L4: 0
B5: American Chemical Society | C5: ACS Chemical Biology | D5: CB | E5: Discovery of β2 Adrenergic Receptor Ligands Using Biosensor Fragment Screening of Tagged Wild-Type Receptor | F5: 947.07 | G5: 76 | H5: 1 | I5: 11 | J5: 0.0036687967 | K5: 0.9963312 | L5: 0
A6: PMID: 24015914 PMC3833349 | B6: American Chemical Society | C6: ACS Chemical Biology | D6: CB | E6: Discovery of an allosteric inhibitor binding site in 3-oxo-acyl-ACP reductase from Pseudomonas aeruginosa | F6: 1267.76 | H6: 1 | I6: 21 | J6: 0.08205373 | K6: 0.91794627 | L6: 0
A7: : PMC3805332 | B7: American Chemical Society | C7: ACS Chemical Biology | D7: CB | E7: Synthesis of alpha-glucan in mycobacteria involves a hetero-octameric complex of trehalose synthase TreS and maltokinase Pep2 | F7: 2286.73 | G7: 179 | H7: 0 | I7: 9 | J7: 0.64735029 | K7: 0.35264971 | L7: 0
A8: PMCID: PMC3656742 | B8: American Chemical Society | C8: ACS Chemical Neuroscience | D8: CN | E8: Continuous online microdialysis using microfluidic sensors: dynamic neuro-metabolic changes during spreading depolarisation | F8: 1186.8 | G8: 45 | H8: 1 | I8: 18 | J8: 0.42829475 | K8: 0.57170525 | L8: 0
A9: PMCID: 3584654 | B9: AMERICAN CHEMICAL SOCIETY | C9: ACS NANO | D9: NANO | E9: HYDROXY-TERMINATED CONJUGATED POLYMER NANOPARTICLES HAVE NEAR-UNITY BRIGHT FRACTION | F9: 642.89 | G9: 60 | H9: 0 | I9: 17 | J9: 0.27927524 | K9: 0.72072476 | L9: 0
A10: 23373658 | B10: American Chemical Society Publications | C10: ACS Nano | D10: NANO | E10: Skin dendritic cell targeting via microneedle arrays laden with antigen-encapsulated poly-D,L-lactide-co-glycolide nanoparticles induces efficient antitumor and antiviral immune responses. | F10: 693.39 | G10: 606 | H10: 0 | I10: na | J10: 0.84485895 | K10: 0.15514105 | L10: 0
A11: PMCID: PMC3727331 | B11: International Union of Crystallography | C11: Acta Crystallographica Section D, Biological Crystallography | D11: BIOC | E11: Clustering procedures for the optimal selection of data sets from multiple crystals in macromolecular crystallography | F11: 771.42 | G11: 480 | H11: 1 | I11: 22 | J11: 0.90950792 | K11: 0.090492082 | L11: 0
A12: PMCID: PMC3565438 | B12: International Union of Crystallography | C12: Acta Crystallographica Section D: Biological Crystallography | D12: BIOC | E12: Intensity statistics in the presence of translational non-crystallographic symmetry | F12: 773.74 | G12: 690 | H12: 1 | I12: 3 | J12: 0.65722673 | K12: 0.34277327 | L12: 0
A13: PMCID: PMC3668577 | B13: International Union of Crystallography (iucr) | C13: Acta Crystallographica Section F: Structural Biology and Crystallization Communications | D13: STRUC | E13: Structure of diaminohydroxyphosphoribosylaminopyrimidine deaminase/5-amino-6-(5-phosphoribosylamino)uracil reductase from Acinetobacter baumannii. | F13: 785.6 | G13: 603 | I13: 32 | J13: 0.54983986 | K13: 0.45016014 | L13: 0
A14: PMCID: PMC3606566 | B14: International Union of Crystallography (iucr) | C14: Acta Crystallographica Section F: Structural Biology and Crystallization Communications | D14: STRUC | E14: Structure of Pseudomonas aeruginosa inosine 5'-monophosphate dehydrogenase | F14: 807.67 | G14: 485 | H14: 0 | I14: 40 | J14: 0.5395541 | K14: 0.4604459 | L14: 0
A15: PMC3498934 | B15: International Union of Crystallography | C15: Acta Crystallographica, Section D | D15: BIOC | E15: Nearest-cell: a fast and easy tool for locating crystal matches in the PDB. | F15: 757.18 | G15: 15 | H15: 0 | I15: 49 | J15: 0.9176209 | K15: 0.082379105 | L15: 0
A16: PMID:22993091 PMC3447403 | B16: International Union of Crystallography | C16: Acta Crystallography D | D16: BIOC | E16: Crystallization, dehydration and experimental phasing of WbdD, a bifunctional kinase and methyltransferase from Escherichia coli O9a | F16: 774.19 | G16: 376 | H16: 1 | I16: 15 | J16: 0.54700917 | K16: 0.45299083 | L16: 0
A17: PMC3087623 | B17: International Union of Crystallography | C17: Acta D | D17: ACTD | E17: Structure of HLA-A*0301 in complex with a peptide of proteolipid protein: insights into the role of HLA-A alleles in susceptibility to multiple sclerosis. | F17: 750.16 | G17: 904 | H17: 1 | I17: 19 | J17: 0.10131625 | K17: 0.89868375 | L17: 0
A18: PMC3808818 | B18: Society for Publication of Acta Dermato-Venereologica | C18: Acta Dermato Venereologica | D18: ACTV | E18: The Importance of a Full Clinical Examination: Assessment of Index Lesions Referred to a Skin Cancer Clinic Without a Total Body Skin Examination Would Miss One in Three Melanomas | F18: 653.96 | G18: 322 | H18: 1 | I18: 25 | J18: 0.18407886 | K18: 0.81592114 | L18: 0
A19: PMID: 23828613 (July 2013 Epub) | B19: Springer | C19: Acta Diabetologica | D19: ACTD | E19: A rare SNP in pre-miR-34a is associated with increased levels of miR-34a in pancreatic beta cells | F19: $2336.28 | G19: 544 | H19: 0 | I19: na | J19: 0.21081329 | K19: 0.78918671 | L19: 0
A20: PMC3374517 | B20: International Union of Crystallography | C20: ACTA F | D20: ACTF | E20: Crystallization and preliminary crystallographic analysis of the major capsid proteins VP16 and VP17 of bacteriophage P23-77 | F20: 754.9 | G20: 476 | H20: 1 | I20: 19 | J20: 0.29987596 | K20: 0.70012404 | L20: 0
A21: PMC3549237 | B21: Springer | C21: Acta Neuropathol | D21: ACTN | E21: Overexpression of human wild-type FUS causes progressive motor neuron degeneration in an age- and dose-dependent fashion | F21: 1901.04 | G21: 666 | H21: 0 | I21: na | J21: 0.29481324 | K21: 0.70518676 | L21: 0
B22: Springer | C22: Acta Neuropathologica | D22: ACTN | E22: Î±-Synucleinopathy associated with G51D SNCA mutation: A link between Parkinson's disease and multiple system atrophy? | F22: 1884.01 | G22: 94 | H22: 1 | I22: 10 | J22: 0.38723498 | K22: 0.61276502 | L22: 0
A23: PMC3661931 | B23: Springer | C23: Acta Neuropathologica | D23: ACTN | E23: Insufficient OPC migration into demyelinated lesions is a cause of poor remyelination in MS and mouse models | F23: 2250.97 | G23: 62 | H23: 1 | I23: 26 | J23: 0.32758913 | K23: 0.67241087 | L23: 0
A24: 3535376 | B24: Springer | C24: Acta Neuropathologica | D24: ACTN | E24: Unravelling the enigma o selective vulnerability in neurodegeneration: motor neurons resistant to degeneration in ALS show distinct gene expression characteristics and decreased susceptibility to excitotoxicity | F24: 7299879.1 | G24: 188 | H24: 1 | I24: 34 | J24: 0.0191216 | K24: 0.9808784 | L24: 0
A25: PMC3798121 | B25: Wiley-Blackwell | C25: Acta Opthalmologica | D25: ACTO | E25: Visual and psychological morbidity among patients with autosomal dominant optic atrophy | F25: 2270.16 | G25: 764 | H25: 0 | I25: 15 | J25: 0.8045102 | K25: 0.1954898 | L25: 0
A26: 21624095 PMCID: PMC3734623 | B26: Wiley | C26: Acta Physiol | D26: ACTP | E26: Integration of transient receptor potential canonical channels with lipids | F26: 1991.5 | G26: 513 | H26: 0 | I26: 8 | J26: 0.34607205 | K26: 0.65392795 | L26: 0
A27: In Process | B27: Wiley | C27: Addiction | D27: ADCT | E27: Acute alcohol-related dysfunction as a predictor of employment status in a longitudinal study of working age men in Izhevsk, Russia. | F27: 1919.51 | G27: 180 | H27: 0 | I27: 43 | J27: 0.96653617 | K27: 0.033463833 | L27: 0
A28: 23734913 | B28: Wiley | C28: Addiction | D28: ADCT | E28: Childhood conduct disorder trajectories, prior risk factors and cannabis use at age 16: birth cohort study | F28: 2352.94 | G28: 520 | H28: 0 | I28: 31 | J28: 0.086637113 | K28: 0.91336289 | L28: 0
B29: Springer | C29: Advances in Experimental Medicine and Biology | D29: AEMB | E29: Wavelet cross-correlation to investigate regional variations in cerebral oxygenation in infants supported on extracorporeal membrane oxygenation | F29: 1928.45 | G29: 818 | H29: 0 | I29: 15 | J29: 0.78811469 | K29: 0.21188531 | L29: 0
B30: Springer | C30: Advances in Experimental Medicine and Biology | D30: AEMB | E30: Modelling Cerebrovascular Reactivity: A Novel Near-Infrared Biomarker of Cerebral Autoregulation? | F30: 1928.46 | G30: 153 | H30: 1 | I30: 1 | J30: 0.46789626 | K30: 0.53210374 | L30: 0
B31: Springer | C31: Advances in Experimental Medicine and Biology | D31: AEMB | E31: Normobaric hyperoxia does not change optical scattering or pathlength but does increase oxidised cytochrome C oxidase concentration in patients with brain injury | F31: 1928.46 | G31: 606 | H31: 0 | I31: 20 | J31: 0.32231037 | K31: 0.67768963 | L31: 0
B32: Springer | C32: Advances in Experimental Medicine and Biology | D32: AEMB | E32: Oscillations in cerebral haemodynamics in patients with falciparum malaria | F32: 1928.46 | G32: 288 | H32: 1 | I32: 2 | J32: 0.45128438 | K32: 0.54871562 | L32: 0
A33: 21948184 PMC3528370 | B33: SPRINGER-VERLAG GMBH | C33: Age | D33: AGEA | E33: The dominant human conjunctival epithelial CD8αβ+ T cell population is maintained with age but the number of CD4+ T cells increases. | F33: 2338.28 | G33: 528 | H33: 1 | I33: 9 | J33: 0.26363814 | K33: 0.73636186 | L33: 0
A34: 23340916 | B34: Springer-Verlag GMBH & Ci | C34: AGE | D34: AGEA | E34: Voluntary exercise can strengthen the circadian system in aged mice | F34: 2002 | G34: 420 | H34: 1 | I34: 45 | J34: 0.10124067 | K34: 0.89875933 | L34: 0
A35: PMID: 23672932 PMC3684112 | B35: Oxford University Press | C35: Age and Ageing | D35: AGEA | E35: Early diagnosis and treatment of HIV infection: magnitude of benefit is greatest in older adults | F35: 2040 | G35: 371 | H35: 1 | I35: 25 | J35: 0.99817275 | K35: 0.0018272506 | L35: 0
B36: Cambridge University Press | C36: Ageing & Society | D36: AGES | E36: Who cares? Implications of care-giving and -receiving by HIV-infected or -affected older | F36: 1695 | G36: 363 | H36: 0 | I36: 2 | J36: 0.88108645 | K36: 0.11891355 | L36: 0
A37: print published August 2013 | B37: Wiley | C37: Aging Cell | D37: AGIC | E37: TORC1 signaling inhibition by rapamycin and caffeine affect lifespan, global gene expression and cell proliferation of fission yeast | F37: 1970.57 | G37: 288 | I37: 41 | J37: 0.51888946 | K37: 0.48111054 | L37: 0
A38: PMC3713766 | B38: Wolters Kluwer | C38: AIDS | D38: AIDAIDS | E38: HIV infected adolescents in Southern Africa can achieve good treatment outcomes: Results from a large retrospective cohort study. | F38: 1968.63 | G38: 372 | H38: 0 | I38: 27 | J38: 0.72814813 | K38: 0.27185187 | L38: 0
A39: 3748854 | B39: Wolters Kluwer Health | C39: AIDS | D39: AIDAIDS | E39: Evaluation of an empiric risk screening score to identify acute and early HIV-1 infection among MSM in Coastal Kenya. | F39: $1834.77 | G39: 968 | H39: 0 | I39: na | J39: 0.55407174 | K39: 0.44592826 | L39: 1582
A40: PMCID: PMC3647051 | B40: Wolters Kluwer N.V./Lippinott | C40: AIDS | D40: AIDAIDS | E40: Grassroots Community Organisations' Contribution to the Scale-Up of HIV Testing and Counselling Services in Zimbabwe | F40: 2374.52 | G40: 202 | H40: 1 | I40: 20 | J40: 0.43837387 | K40: 0.56162613 | L40: 0
...
